Workbook

Sheet Leeme
A1: 03_Anexo_Calculos | Almena Foods
A2: Anexo auditable de la propuesta del Ingeniero de Producto IA
A4: Cómo leer este archivo
A5: Texto azul | B5: Dato de entrada o supuesto editable
A6: Fondo amarillo | B6: Palanca clave: cámbiela y todo se recalcula
A7: Texto verde | B7: Referencia a otra hoja
A8: Texto negro | B8: Fórmula
A10: Hojas
A11: Datos | B11: Datos del material (02, 03, 05) con fuente y confiabilidad
A12: Supuestos | B12: Registro de supuestos S-xx; las palancas están en amarillo
A13: Valor_F1 | B13: Dimensionamiento de la familia Análisis comercial (IA-01, IA-03, IA-06, IA-07)
A14: Promesas | B14: Promesas de negocio expresadas en cifras, marcadas como hipótesis
A15: PBIs | B15: Backlog de 24 PBIs por área con horas mín / probable / máx
A16: Capacidad | B16: Suma de PBIs en tres escenarios contra las restricciones de 90 días
A17: Priorizacion | B17: Puntajes de candidatas y resultado de la priorización
A18: Rutas | B18: Construir, comprar, componer o sin IA: matriz ponderada
A19: Fondo_Externo | B19: Uso propuesto del fondo externo de hasta COP 30 M (opción C)
A20: Uso_Recursos | B20: Cierre: en qué se usa cada hora de cada área y cuánto queda en reserva
A21: Portafolio | B21: Las 15 solicitudes con familia, esfuerzo del solicitante y decisión
A22: Decisiones | B22: Registro de decisiones D-xx
A24: Reglas | B24: Horas liberadas no son ahorro. Ahorro capturable solo con mecanismo explícito (Supuestos S-12). Costos internos son imputados, no caja.

Sheet Datos
A1: Datos del material
A2: Solo datos entregados. Valores en azul. Fuente y confiabilidad según el archivo 03.
A4: ID | B4: Variable | C4: Valor | D4: Unidad | E4: Fuente (archivo, hoja) | F4: Confiabilidad | G4: Nota crítica
A5: DAT-01 | B5: Analistas de mercadeo | C5: 12 | D5: personas | E5: 03, Operacion | F5: Confirmado | G5: 8 de los 12 en la muestra de tiempos
A6: DAT-02 | B6: Analistas con bitácora de tiempos | C6: 8 | D6: personas | E6: 03, Operacion | F6: Observado | G6: No extrapolar sin declarar supuesto
A7: DAT-03 | B7: Horas semanales por analista en análisis | C7: 9 | D7: h/persona/semana | E7: 03, Operacion | F7: Observado en muestra | G7: Puede no representar a los 12
A8: DAT-04 | B8: Semanas laborables anuales | C8: 46 | D8: semanas/año | E8: 03, Operacion | F8: Estimación | G8: Solo como supuesto de proyección
A9: DAT-05 | B9: Costo laboral integral analista | C9: 68000 | D9: COP/h | E9: 03, Operacion | F9: Estimación de costo | G9: Costo imputado, NO ahorro de caja
A10: DAT-06 | B10: Informes comerciales preparados | C10: 74 | D10: informes/mes | E10: 03, Operacion | F10: Confirmado | G10: No todos los hacen los mismos 8 analistas
A11: DAT-07 | B11: Fracción de informes con reproceso | C11: 0.18 | D11: fracción | E11: 03, Operacion | F11: Confirmado
A12: DAT-08 | B12: Horas adicionales por informe reprocesado | C12: 2.2 | D12: h/informe | E12: 03, Operacion | F12: Estimación | G12: Incluido en las horas semanales; no sumar dos veces
A13: DAT-09 | B13: Correcciones de información comercial | C13: 26 | D13: h/mes | E13: 03, Operacion | F13: Estimación | G13: Carga del equipo de datos; no es costo evitable validado
A14: DAT-10 | B14: Alertas de calidad identificadas | C14: 20 | D14: casos/mes | E14: 03, Operacion | F14: Confirmado | G14: No todas son errores
A15: DAT-11 | B15: Alertas que resultaron errores | C15: 6 | D15: casos/mes | E15: 03, Operacion | F15: Estimación | G15: Sin impacto económico atribuido
A16: DAT-12 | B16: Ventas netas anuales de Brío | C16: 36000000000 | D16: COP/año | E16: 03, Negocio y alcance | F16: Confirmado | G16: Total de la marca; NO es beneficio del proyecto
A17: DAT-13 | B17: Margen de contribución medio de Brío | C17: 0.26 | D17: fracción | E17: 03, Negocio y alcance | F17: Estimación | G17: Promedio histórico, no margen incremental
A18: DAT-14 | B18: Campañas comerciales al año | C18: 48 | D18: campañas/año | E18: 03, Negocio y alcance | F18: Confirmado | G18: Sin dato de impacto incremental
A19: DAT-15 | B19: Tiempo mediano de propuesta creativa | C19: 8 | D19: días hábiles | E19: 03, Negocio y alcance | F19: Observado | G19: No medido su efecto en ventas
A20: DAT-16 | B20: Investigaciones de consumidor | C20: 36 | D20: estudios/año | E20: 03, Negocio y alcance | F20: Confirmado | G20: Sin baseline de tiempo de lectura
A21: DAT-17 | B21: Sesiones de decisión con análisis formales | C21: 18 | D21: sesiones/trimestre | E21: 03, Negocio y alcance | F21: Conteo | G21: Sin indicador de calidad de decisión
A22: DAT-18 | B22: Tasa de quiebre reportada | C22: 0.032 | D22: fracción | E22: 03, Negocio y alcance | F22: No auditado | G22: Cobertura incompleta
A23: DAT-19 | B23: Error de pronóstico (MAPE total) | C23: 0.26 | D23: fracción | E23: 03, Negocio y alcance | F23: No auditado | G23: Sin desagregación
... A28: DAT-24 | B28: Disponibilidad equipo de datos | C28: 35 | D28: h/90 días | E28: 03, Recursos y costos | F28: Confirmado | G28: Cuello de botella
A29: DAT-25 | B29: Disponibilidad seguridad tecnológica | C29: 12 | D29: h/90 días | E29: 03, Recursos y costos | F29: Confirmado
A30: DAT-26 | B30: Disponibilidad expertos de Mercadeo | C30: 20 | D30: h/90 días | E30: 03, Recursos y costos | F30: Estimación | G30: No garantizadas
A31: DAT-27 | B31: Tarifa de oportunidad ingeniería | C31: 105000 | D31: COP/h | E31: 03, Recursos y costos | F31: Costo imputado | G31: No es salida de caja
A32: DAT-28 | B32: Tarifa de oportunidad datos | C32: 85000 | D32: COP/h | E32: 03, Recursos y costos | F32: Costo imputado | G32: No es salida de caja
A33: DAT-29 | B33: Tarifa de oportunidad seguridad | C33: 120000 | D33: COP/h | E33: 03, Recursos y costos | F33: Costo imputado | G33: No es salida de caja
A34: DAT-30 | B34: Techo de desembolso externo para piloto | C34: 30000000 | D34: COP/90 días | E34: 03, Recursos y costos | F34: Condicionado | G34: Requiere aprobación
A35: DAT-31 | B35: Contratos de IA aprobados | C35: 0 | D35: contratos | E35: 03, Recursos y costos | F35: Confirmado | G35: Compras requieren ciclo de aprobación
A36: DAT-32 | B36: Promesa de Comercial: aumento de ventas | C36: 0.02 | D36: fracción | E36: 03, Hipotesis no validadas | F36: Hipótesis | G36: Sin prueba causal ni control
A37: DAT-33 | B37: Promesa de Mercadeo: ahorro de tiempo de análisis | C37: 0.4 | D37: fracción | E37: 03, Hipotesis no validadas | F37: Hipótesis | G37: Sin ensayo controlado
A38: DAT-34 | B38: Plazo del CEO para validar IA-05 | C38: 45 | D38: días | E38: 05, Mensaje 02; 02, IA-05 | F38: Evidencia (pedido) | G38: Pide validación, no producto
A39: DAT-35 | B39: Días del horizonte | C39: 90 | D39: días | E39: 01_Contexto | F39: Confirmado
A40: DAT-36 | B40: Tokens promedio por pregunta en la prueba con IA | C40: 4327 | D40: tokens/pregunta | E40: copiloto-brio, out/evaluacion.json (18 preguntas) | F40: Observado | G40: Prueba con datos sintéticos; mín 1.991, máx 7.266

Sheet Supuestos
A1: Registro de supuestos
A2: Amarillo = palanca editable. Los demás se calculan desde Datos.
A4: ID | B4: Descripción | C4: Valor | D4: Unidad | E4: Fórmula / fuente | F4: Confiabilidad
A5: S-01 | B5: Horas anuales de análisis observadas (8 analistas) | C5: =Datos!$C$6*Datos!$C$7*Datos!$C$8 -> 3312 | D5: h/año | E5: DAT-02 × DAT-03 × DAT-04 | F5: Observado + estimación
A6: S-02 | B6: Horas anuales si los 12 analistas trabajan igual (solo escenario) | C6: =Datos!$C$5*Datos!$C$7*Datos!$C$8 -> 4968 | D6: h/año | E6: DAT-01 × DAT-03 × DAT-04 | F6: Hipótesis: medir a los otros 4
A7: S-03 | B7: Horas de reproceso al mes (ya incluidas en S-01) | C7: =Datos!$C$10*Datos!$C$11*Datos!$C$12 -> 29.304 | D7: h/mes | E7: DAT-06 × DAT-07 × DAT-08 | F7: Confirmado + estimación
A8: S-04 | B8: Precisión actual de las alertas | C8: =Datos!$C$15/Datos!$C$14 -> 0.3 | D8: fracción | E8: DAT-11 / DAT-10 | F8: Estimación
A9: S-05 | B9: Brecha de capacidad mínima (esfuerzo bajo solicitado / 240 h) | C9: =Portafolio!$E$21/Datos!$C$27 -> 5.0625 | D9: veces | E9: Portafolio E21 / DAT-23 | F9: Rangos no validados
A10: S-06 | B10: Costo imputado de toda la capacidad interna 90 días (sin expertos) | C10: =Datos!$C$27*Datos!$C$31+Datos!$C$28*Datos!$C$32+Datos!$C$29*Datos!$C$33 -> 29615000 | D10: COP | E10: Horas × tarifa por recurso | F10: Costo imputado
A11: S-07 | B11: Escenario conservador de reducción de horas de análisis | C11: 0.1 | D11: fracción | E11: Supuesto propio, anclado al reproceso (S-09) | F11: Hipótesis
A12: S-08 | B12: Escenario base de reducción de horas de análisis | C12: 0.2 | D12: fracción | E12: Supuesto propio | F12: Hipótesis
A13: S-09 | B13: Reproceso como fracción de las horas observadas | C13: =C7*12/C5 -> 0.10617391 | D13: fracción | E13: S-03 × 12 / S-01 | F13: Confirmado + estimación
A14: S-10 | B14: Sesiones de decisión dentro del plazo de 45 días | C14: =Datos!$C$21*Datos!$C$38/Datos!$C$39 -> 9 | D14: sesiones | E14: DAT-17 × DAT-34 / DAT-35 (reparto uniforme) | F14: Conteo + supuesto
A15: S-11 | B15: [Retirado por D-15] Imprevistos 15 % sobre ingeniería de IA-01; reemplazado por rangos mín/máx por PBI | C15: 0.15 | D15: fracción | E15: Ya no se usa en cálculos | F15: Retirado
A16: S-12 | B16: Fracción de horas liberadas capturadas como ahorro de caja | C16: 0 | D16: fracción | E16: 0 hasta que Mercadeo defina mecanismo (no contratar, quitar horas extra, reasignación medible) | F16: Por confirmar
A17: S-13 | B17: Incluir prueba IA-04 en el plan (1 = sí, 0 = no) | C17: 0 | D17: indicador | E17: Condicionada: herramienta ya licenciada y horas de expertos libres | F17: Decisión D-09
A18: S-14 | B18: Reserva mínima de ingeniería para cambios de Dirección | C18: 40 | D18: h | E18: Supuesto propio | F18: Estimación
A19: S-15 | B19: Brecha de capacidad máxima (esfuerzo alto solicitado / 240 h) | C19: =Portafolio!$F$21/Datos!$C$27 -> 9.1041667 | D19: veces | E19: Portafolio F21 / DAT-23 | F19: Rangos no validados
A20: S-16 | B20: Meta de reducción de horas del piloto IA-01 | C20: =C12 -> 0.2 | D20: fracción | E20: Igual a S-08 (D-13) | F20: Hipótesis
A21: S-17 | B21: Umbral mínimo de reducción para seguir | C21: =C11 -> 0.1 | D21: fracción | E21: Igual a S-07 (D-13) | F21: Hipótesis
A22: S-18 | B22: Meta de uso útil del copiloto en el grupo piloto | C22: 0.6 | D22: fracción | E22: Supuesto propio, a acordar con Mercadeo | F22: Hipótesis
A23: S-19 | B23: Umbral mínimo de uso útil | C23: 0.4 | D23: fracción | E23: Supuesto propio | F23: Hipótesis
A24: S-20 | B24: Meta de reproceso en grupo piloto (mitad de DAT-07) | C24: =Datos!$C$11/2 -> 0.09 | D24: fracción | E24: DAT-07 / 2 | F24: Hipótesis
A25: S-21 | B25: Duración de la medición del piloto | C25: 4 | D25: semanas | E25: Supuesto propio (+ semana 0 de línea base) | F25: Estimación
A26: S-22 | B26: Analistas por grupo (piloto y control) | C26: 4 | D26: personas | E26: Mitad de los 8 con bitácora (DAT-02) | F26: Estimación
A27: S-23 | B27: Canal corporativo: Microsoft 365 / Teams. Plan B: web interna con inicio de sesión corporativo | C27: Supuesto | D27: texto | E27: Estándar del sector [Por confirmar] | F27: Supuesto
A28: S-24 | B28: Modelo de IA dentro del acuerdo de nube vigente, previa revisión de Seguridad. Plan B: modelo bajo techo de COP 30 M con aprobación | C28: Supuesto | D28: texto | E28: Evita proveedor nuevo [Por confirmar] | F28: Supuesto
A29: S-25 | B29: Ventas salen del ERP en extractos CSV | C29: Evidencia | D29: texto | E29: 02, IA-01: 'CSV y documentos dispersos' | F29: Evidencia
A30: S-26 | B30: Tabla de ventas agregada (mes, canal, región), sin datos personales. Plan B: anonimizar | C30: Supuesto | D30: texto | E30: El copiloto no usa datos de clientes [Por confirmar con Seguridad] | F30: Supuesto
A31: S-27 | B31: Preguntas por analista por día en el piloto | C31: 10 | D31: preguntas | E31: Supuesto propio | F31: Estimación
A32: S-28 | B32: Días hábiles por mes | C32: 20 | D32: días | E32: Supuesto propio | F32: Estimación
A33: S-30 | B33: Capacidad de trimestres siguientes similar a la actual (240/35/12/20 h) | C33: Supuesto | D33: texto | E33: Base de la hoja de ruta H2-H3 [Por confirmar] | F33: Supuesto
A34: S-29 | B34: Tokens del modelo al mes en el piloto | C34: =C26*C31*C32*Datos!$C$40 -> 3461600 | D34: tokens/mes | E34: S-22 × S-27 × S-28 × DAT-36 | F34: Estimación
A35: S-31 | B35: Tarifa externa por hora de datos | C35: 120000 | D35: COP/h | E35: Supuesto propio: ~40 % sobre la tarifa interna de datos (DAT-28) [Por confirmar con Compras] | F35: Supuesto
A36: S-32 | B36: Contratar servicios de datos sigue el proceso normal de compras (no es proveedor de IA) | C36: Supuesto | D36: texto | E36: [Por confirmar con Compras] | F36: Supuesto
A37: S-33 | B37: Horas externas para informes automáticos (IA-06) | C37: 75 | D37: h | E37: Tope del rango del solicitante (02, IA-06) | F37: Estimación
A38: S-34 | B38: Horas externas para auditar datos de quiebres y pronóstico (IA-08/14) | C38: 40 | D38: h | E38: Supuesto propio | F38: Estimación
A39: S-35 | B39: Respaldo del costo del modelo si no está en el acuerdo de nube | C39: 3000000 | D39: COP | E39: Supuesto propio; tarifa del modelo [Por confirmar]; volumen en S-29 | F39: Supuesto
A40: S-36 | B40: Horas externas de datos para la base única (cubre el escenario máximo) | C40: 15 | D40: h | E40: Brecha de Datos en escenario máximo: 48 − 35 = 13 h, redondeado | F40: Estimación
A41: S-37 | B41: Almena usa Microsoft 365 con Copilot Chat (incluido sin costo adicional, con protección de datos empresariales) | C41: Supuesto | D41: texto | E41: Copilot Chat sin costo adicional para cuentas Entra con M365 elegible (microsoft.com, precios Microsoft 365 Copilot) [Por confirmar con TI] | F41: Supuesto + evidencia pública
...

Sheet Valor_F1
A1: Familia 1: Análisis comercial | Dimensionamiento
A2: Productividad ≠ ahorro. El valor imputado NO es caja.
A4: Concepto | B4: Valor | C4: Unidad | D4: Fórmula | E4: Tipo
A5: Horas anuales de análisis observadas | B5: =Supuestos!$C$5 -> 3312 | C5: h/año | D5: S-01 | E5: [ESTIMACIÓN]
A6: Horas si se extrapola a 12 analistas | B6: =Supuestos!$C$6 -> 4968 | C6: h/año | D6: S-02 | E6: [HIPÓTESIS]
A7: Horas de reproceso al año (incluidas arriba, no sumar) | B7: =Supuestos!$C$7*12 -> 351.648 | C7: h/año | D7: S-03 × 12 | E7: [ESTIMACIÓN]
A8: Reproceso como % de horas observadas | B8: =Supuestos!$C$13 -> 0.10617391 | C8: fracción | D8: S-09 | E8: [ESTIMACIÓN]
A11: Escenarios de productividad (sobre horas observadas)
A12: Escenario | B12: % reducción | C12: Horas liberadas/año | D12: Valor imputado (COP/año) | E12: Ahorro capturable (COP/año) | F12: Nota
A13: Conservador | B13: =Supuestos!$C$11 -> 0.1 | C13: =B13*$B$5 -> 331.2 | D13: =C13*Datos!$C$9 -> 22521600 | E13: =D13*Supuestos!$C$16 -> 0 | F13: Supuesto propio
A14: Base | B14: =Supuestos!$C$12 -> 0.2 | C14: =B14*$B$5 -> 662.4 | D14: =C14*Datos!$C$9 -> 45043200 | E14: =D14*Supuestos!$C$16 -> 0 | F14: Supuesto propio
A15: Promesa de Mercadeo | B15: =Datos!$C$37 -> 0.4 | C15: =B15*$B$5 -> 1324.8 | D15: =C15*Datos!$C$9 -> 90086400 | E15: =D15*Supuestos!$C$16 -> 0 | F15: Hipótesis sin ensayo; no usar como meta
A17: Lectura: el valor imputado mide lo que valen las horas, no plata ahorrada. El ahorro capturable es cero mientras S-12 = 0 %.
A19: Tipos de valor de la familia
A20: Tipo de valor | B20: Contenido | C20: Confiabilidad
A21: Productividad | B21: Horas liberadas según escenarios (filas 13-15) | C21: Hipótesis
A22: Ahorro capturable | B22: Cero por defecto; depende de S-12 | C22: Por confirmar
A23: Impacto comercial | B23: Indirecto vía mejores análisis de Brío; no atribuible en 90 días | C23: Hipótesis
A24: Estratégico | B24: Definición única de ventas netas; base para IA-02 e IA-05 | C24: Cualitativo
A26: Recuperación en términos imputados (no es caja)
A27: Escenario | B27: % reducción | C27: Analistas | D27: Valor imputado (COP/año) | E27: Costo imputado IA-01 (COP) | F27: Meses para recuperar
A28: Pesimista | B28: =Supuestos!$C$11 -> 0.1 | C28: =Datos!$C$6 -> 8 | D28: =B28*C28*Datos!$C$7*Datos!$C$8*Datos!$C$9 -> 22521600 | E28: =Capacidad!$G$20 -> 17925000 | F28: =IF(D28=0,"n/a",E28/D28*12) -> 9.5508312
A29: Base | B29: =Supuestos!$C$12 -> 0.2 | C29: =Datos!$C$6 -> 8 | D29: =B29*C29*Datos!$C$7*Datos!$C$8*Datos!$C$9 -> 45043200 | E29: =Capacidad!$G$20 -> 17925000 | F29: =IF(D29=0,"n/a",E29/D29*12) -> 4.7754156
A30: Optimista (12 analistas) | B30: =Supuestos!$C$12 -> 0.2 | C30: =Datos!$C$5 -> 12 | D30: =B30*C30*Datos!$C$7*Datos!$C$8*Datos!$C$9 -> 67564800 | E30: =Capacidad!$G$20 -> 17925000 | F30: =IF(D30=0,"n/a",E30/D30*12) -> 3.1836104
A31: Base, cargando al copiloto todo el fondo pedido | B31: =Supuestos!$C$12 -> 0.2 | C31: =Datos!$C$6 -> 8 | D31: =D29 -> 45043200 | E31: =Capacidad!$G$20+Fondo_Externo!$F$10 -> 36525000 | F31: =IF(D31=0,"n/a",E31/D31*12) -> 9.7306586
A32: Lectura: meses en que las horas liberadas igualan la inversión. Fila 31 = peor caso (parte del fondo es para informes y auditoría). Ninguna cifra es ahorro de caja.

Sheet Promesas
A1: Promesas de negocio expresadas en cifras
A2: Todo en esta hoja es [HIPÓTESIS]. Sirve para mostrar el tamaño de la promesa, no el beneficio.
A4: Concepto | B4: Valor | C4: Unidad | D4: Fórmula | E4: Por qué no es beneficio
A5: Ventas anuales de Brío | B5: =Datos!$C$16 -> 36000000000 | C5: COP/año | D5: DAT-12 | E5: Es el total de la marca
A6: Promesa de aumento de ventas (Comercial) | B6: =Datos!$C$36 -> 0.02 | C6: fracción | D6: DAT-32 | E6: Sin grupo de control
A7: Ventas incrementales prometidas | B7: =B5*B6 -> 720000000 | C7: COP/año | D7: B5 × B6 | E7: No resta ventas que igual habrían ocurrido
A8: Margen medio de Brío | B8: =Datos!$C$17 -> 0.26 | C8: fracción | D8: DAT-13 | E8: Promedio histórico, no incremental
A9: Margen bruto de la promesa | B9: =B7*B8 -> 187200000 | C9: COP/año | D9: B7 × B8 | E9: Antes de costo de descuentos y canibalización
A10: Precisión actual de alertas de datos | B10: =Supuestos!$C$8 -> 0.3 | C10: fracción | D10: S-04 | E10: 7 de cada 10 alertas no son errores
A11: Tickets repetitivos al mes | B11: =Datos!$C$24*Datos!$C$25 -> 275 | C11: tickets/mes | D11: DAT-20 × DAT-21 | E11: Repetitivo no es automatizable con seguridad

Sheet PBIs
A1: Backlog de PBIs por área | Estimación por rangos
A2: Horas mín / probable / máx en azul (estimación propia, a validar con cada área). Incluido: 1 = en el plan.
A4: ID | B4: Frente | C4: Área responsable | D4: Título (acción) | E4: Para | F4: Criterio de aceptación | G4: Puntos | H4: Ing mín | I4: Ing prob | J4: Ing máx | K4: Datos mín | L4: Datos prob | M4: Datos máx | N4: Seg mín | O4: Seg prob | P4: Seg máx | Q4: Exp mín | R4: Exp prob | S4: Exp máx | T4: Incluido | U4: Nota / otras áreas
A5: PBI-01 | B5: IA-01 | C5: Datos | D5: Acordar la definición única de ventas netas | E5: Que todos usen la misma cifra | F5: Definición firmada por Mercadeo, Comercial, Finanzas y Datos | G5: 5 | H5: 0 | I5: 0 | J5: 0 | K5: 4 | L5: 6 | M5: 8 | N5: 0 | O5: 0 | P5: 0 | Q5: 1 | R5: 2 | S5: 3 | T5: 1 | U5: Comercial y Finanzas: 2-4 h
A6: PBI-02 | B6: IA-01 | C6: Datos | D6: Inventariar fuentes de ventas de Brío y mapearlas a la definición | E6: Saber de dónde sale cada cifra | F6: Inventario con fuente, dueño y corte por cada fuente | G6: 3 | H6: 0 | I6: 0 | J6: 0 | K6: 3 | L6: 4 | M6: 6 | N6: 0 | O6: 0 | P6: 0 | Q6: 0 | R6: 0 | S6: 0 | T6: 1
A7: PBI-03 | B7: IA-01 | C7: Datos | D7: Construir la tabla validada de ventas de Brío | E7: Tener una sola fuente confiable | F7: Tabla cuadra 100 % con el cierre de Finanzas en una muestra de meses | G7: 8 | H7: 2 | I7: 4 | J7: 6 | K7: 6 | L7: 8 | M7: 12 | N7: 0 | O7: 0 | P7: 0 | Q7: 0 | R7: 0 | S7: 0 | T7: 1 | U7: Alcance de meses y canales [Por confirmar]
A8: PBI-04 | B8: IA-01 | C8: Datos | D8: Implementar reglas de calidad sobre la tabla (absorbe IA-03) | E8: Detectar errores antes de que lleguen a un informe | F8: Reglas activas y alertas registradas con causa | G8: 5 | H8: 0 | I8: 0 | J8: 0 | K8: 3 | L8: 5 | M8: 7 | N8: 0 | O8: 0 | P8: 0 | Q8: 0 | R8: 0 | S8: 0 | T8: 1 | U8: IA-03 sin IA
A9: PBI-05 | B9: IA-01 | C9: Datos | D9: Dar soporte de datos durante el piloto | E9: Resolver dudas de cifras a tiempo | F9: Dudas atendidas en menos de 1 día hábil | G9: 3 | H9: 0 | I9: 0 | J9: 0 | K9: 2 | L9: 4 | M9: 6 | N9: 0 | O9: 0 | P9: 0 | Q9: 0 | R9: 0 | S9: 0 | T9: 1
A10: PBI-06 | B10: IA-01 | C10: Ingeniería | D10: Definir criterios de aceptación y la batería de preguntas de referencia | E10: Saber qué es una respuesta correcta | F10: Batería aprobada por Mercadeo con respuesta correcta calculada a mano | G10: 5 | H10: 6 | I10: 8 | J10: 10 | K10: 0 | L10: 0 | M10: 0 | N10: 0 | O10: 0 | P10: 0 | Q10: 2 | R10: 3 | S10: 4 | T10: 1
A11: PBI-07 | B11: IA-01 | C11: Ingeniería | D11: Configurar el acceso al modelo de IA aprobado y el entorno | E11: Poder construir sobre una herramienta permitida | F11: Entorno funcionando con el modelo aprobado por Seguridad | G11: 3 | H11: 4 | I11: 6 | J11: 10 | K11: 0 | L11: 0 | M11: 0 | N11: 0 | O11: 0 | P11: 0 | Q11: 0 | R11: 0 | S11: 0 | T11: 1 | U11: Depende de aprobación del modelo
A12: PBI-08 | B12: IA-01 | C12: Ingeniería | D12: Construir la capa que convierte la pregunta en consulta sobre la tabla validada | E12: Que la IA no calcule cifras | F12: 90 % de la batería genera la consulta correcta | G12: 13 | H12: 24 | I12: 32 | J12: 45 | K12: 0 | L12: 0 | M12: 0 | N12: 0 | O12: 0 | P12: 0 | Q12: 0 | R12: 0 | S12: 0 | T12: 1 | U12: Núcleo técnico
A13: PBI-09 | B13: IA-01 | C13: Ingeniería | D13: Construir la ficha de trazabilidad y la respuesta 'no tengo el dato' | E13: Que el analista confíe en cada cifra | F13: 100 % de respuestas con fuente, corte, definición y responsable | G13: 8 | H13: 8 | I13: 12 | J13: 16 | K13: 0 | L13: 0 | M13: 0 | N13: 0 | O13: 0 | P13: 0 | Q13: 0 | R13: 0 | S13: 0 | T13: 1
A14: PBI-10 | B14: IA-01 | C14: Ingeniería | D14: Construir la interfaz simple de preguntas | E14: Que el analista pregunte en lenguaje normal | F14: 4 analistas la usan sin ayuda tras 30 minutos de inducción | G14: 8 | H14: 10 | I14: 16 | J14: 24 | K14: 0 | L14: 0 | M14: 0 | N14: 0 | O14: 0 | P14: 0 | Q14: 0 | R14: 0 | S14: 0 | T14: 1
A15: PBI-11 | B15: IA-01 | C15: Ingeniería | D15: Implementar permisos y registro de preguntas y respuestas | E15: Controlar quién ve qué y auditar | F15: Solo usuarios del piloto acceden; 100 % de interacciones registradas | G15: 8 | H15: 8 | I15: 10 | J15: 14 | K15: 0 | L15: 0 | M15: 0 | N15: 0 | O15: 0 | P15: 0 | Q15: 0 | R15: 0 | S15: 0 | T15: 1
A16: PBI-12 | B16: IA-01 | C16: Ingeniería | D16: Evaluar contra la batería de preguntas y corregir | E16: Llegar al piloto sin cifras erradas | F16: 100 % de cifras coinciden con el cálculo manual | G16: 8 | H16: 12 | I16: 18 | J16: 26 | K16: 0 | L16: 0 | M16: 0 | N16: 0 | O16: 0 | P16: 0 | Q16: 2 | R16: 3 | S16: 4 | T16: 1
A17: PBI-13 | B17: IA-01 | C17: Ingeniería | D17: Acompañar el piloto de 4 semanas y ajustar | E17: Corregir rápido lo que falle | F17: Retro semanal con analistas y ajustes cerrados | G17: 13 | H17: 14 | I17: 20 | J17: 28 | K17: 0 | L17: 0 | M17: 0 | N17: 0 | O17: 0 | P17: 0 | Q17: 4 | R17: 6 | S17: 8 | T17: 1
A18: PBI-14 | B18: IA-01 | C18: Ingeniería | D18: Montar la medición piloto vs control | E18: Saber si el copiloto mejora algo | F18: Tablero con horas, reproceso, exactitud y uso por grupo | G18: 5 | H18: 6 | I18: 8 | J18: 10 | K18: 0 | L18: 0 | M18: 0 | N18: 0 | O18: 0 | P18: 0 | Q18: 0 | R18: 0 | S18: 0 | T18: 1
A19: PBI-15 | B19: IA-01 | C19: Ingeniería | D19: Documentar y traspasar a operación | E19: Que el área opere sin depender del proyecto | F19: Manual y dueño de operación asignado | G19: 5 | H19: 6 | I19: 8 | J19: 10 | K19: 0 | L19: 0 | M19: 0 | N19: 0 | O19: 0 | P19: 0 | Q19: 0 | R19: 0 | S19: 0 | T19: 1
A20: PBI-16 | B20: IA-01 | C20: Seguridad | D20: Revisar arquitectura, datos y proveedor del modelo | E20: Usar IA sin exponer información | F20: Concepto de Seguridad aprobado antes de construir | G20: 3 | H20: 0 | I20: 0 | J20: 0 | K20: 0 | L20: 0 | M20: 0 | N20: 3 | O20: 4 | P20: 6 | Q20: 0 | R20: 0 | S20: 0 | T20: 1 | U20: Ventas sin datos personales [Por confirmar]
A21: PBI-17 | B21: IA-01 | C21: Seguridad | D21: Validar permisos y registros antes del piloto | E21: Salir al piloto con controles | F21: Checklist de Seguridad firmado | G21: 2 | H21: 0 | I21: 0 | J21: 0 | K21: 0 | L21: 0 | M21: 0 | N21: 1 | O21: 2 | P21: 3 | Q21: 0 | R21: 0 | S21: 0 | T21: 1
A22: PBI-18 | B22: IA-02 | C22: Datos | D22: Extraer el histórico de promociones y descuentos de Brío | E22: Tener base para diseñar el experimento | F22: Histórico por región con descuento y fecha | G22: 5 | H22: 0 | I22: 0 | J22: 0 | K22: 4 | L22: 6 | M22: 9 | N22: 0 | O22: 0 | P22: 0 | Q22: 0 | R22: 0 | S22: 0 | T22: 1 | U22: Datos parciales
A23: PBI-19 | B23: IA-02 | C23: Ingeniería | D23: Analizar el histórico y diseñar el experimento por regiones | E23: Probar si las promociones recomendadas venden más | F23: Diseño con regiones piloto y control aprobado por Comercial y Finanzas | G23: 8 | H23: 8 | I23: 12 | J23: 18 | K23: 0 | L23: 0 | M23: 0 | N23: 0 | O23: 0 | P23: 0 | Q23: 1 | R23: 2 | S23: 3 | T23: 1 | U23: Comercial: 3-5 h
A24: PBI-20 | B24: IA-04 | C24: Seguridad | D24: Revisar términos de la herramienta creativa existente | E24: Proteger derechos y datos de marca | F24: Concepto de Seguridad sobre la herramienta | G24: 2 | H24: 0 | I24: 0 | J24: 0 | K24: 0 | L24: 0 | M24: 0 | N24: 1 | O24: 2 | P24: 3 | Q24: 0 | R24: 0 | S24: 0 | T24: =Supuestos!$C$17 -> 0 | U24: Condicionado (S-13)
A25: PBI-21 | B25: IA-04 | C25: Ingeniería | D25: Preparar guía y ejecutar la prueba creativa con 2-3 briefs en Copilot | E25: Saber si acelera piezas aprobadas | F25: Piezas aprobadas y rondas de ajuste medidas | G25: 5 | H25: 6 | I25: 8 | J25: 12 | K25: 0 | L25: 0 | M25: 0 | N25: 0 | O25: 0 | P25: 0 | Q25: 4 | R25: 6 | S25: 8 | T25: =Supuestos!$C$17 -> 0 | U25: Condicionado (S-13)
A26: PBI-22 | B26: IA-05 | C26: Ingeniería | D26: Diseñar la rúbrica con Dirección y calificar la línea base | E26: Tener por primera vez una métrica de calidad de decisión | F26: Rúbrica aprobada y 5-6 documentos calificados | G26: 5 | H26: 6 | I26: 8 | J26: 12 | K26: 0 | L26: 0 | M26: 0 | N26: 0 | O26: 0 | P26: 0 | Q26: 0 | R26: 0 | S26: 0 | T26: 1 | U26: Dirección: 2-4 h [Por confirmar]
A27: PBI-23 | B27: IA-05 | C27: Ingeniería | D27: Preparar instrucciones en Copilot Chat y acompañar 3-4 sesiones | E27: Probar si mejora la calidad del documento sin construir nada | F27: Calificación ciega de documentos con y sin asistente | G27: 3 | H27: 2 | I27: 4 | J27: 6 | K27: 0 | L27: 0 | M27: 0 | N27: 0 | O27: 0 | P27: 0 | Q27: 0 | R27: 0 | S27: 0 | T27: 1 | U27: Usa Copilot Chat de Microsoft 365 (S-37)
A28: PBI-24 | B28: IA-05 | C28: Seguridad | D28: Revisar seguridad de contenido sensible | E28: Proteger información de Dirección | F28: Concepto de Seguridad aprobado | G28: 2 | H28: 0 | I28: 0 | J28: 0 | K28: 0 | L28: 0 | M28: 0 | N28: 1 | O28: 2 | P28: 3 | Q28: 0 | R28: 0 | S28: 0 | T28: 1
A29: PBI-25 | B29: IA-09/10 | C29: Ingeniería | D29: Preparar la evaluación de compra de soporte interno y revisión de contratos | E29: Comprar con datos en el mes 4 sin empezar de cero | F29: Requisitos, documento neutral para proveedores y comparación de lista corta | G29: 3 | H29: 6 | I29: 10 | J29: 14 | K29: 0 | L29: 0 | M29: 0 | N29: 1 | O29: 2 | P29: 3 | Q29: 0 | R29: 0 | S29: 0 | T29: 1 | U29: Sin desembolso; Seguridad revisa términos de datos de la lista corta
A30: PBI-26 | B30: EXT | C30: Ingeniería | D30: Supervisar el trabajo del equipo externo de datos | E30: Que la base única y los informes externos cumplan el estándar | F30: Entregables externos aceptados contra criterios y 0 diferencias | G30: 2 | H30: 4 | I30: 6 | J30: 8 | K30: 1 | L30: 2 | M30: 3 | N30: 0 | O30: 0 | P30: 0 | Q30: 0 | R30: 0 | S30: 0 | T30: 1 | U30: Depende de aprobar el fondo (D-23)
A31: PBI-27 | B31: EXT | C31: Seguridad | D31: Revisar al proveedor externo de datos | E31: Dar acceso a datos de ventas sin riesgo | F31: Concepto de Seguridad y accesos de mínimo privilegio | G31: 2 | H31: 0 | I31: 0 | J31: 0 | K31: 0 | L31: 0 | M31: 0 | N31: 1 | O31: 2 | P31: 3 | Q31: 0 | R31: 0 | S31: 0 | T31: 1 | U31: Depende de aprobar el fondo (D-23)
A32: PBI-28 | B32: IA-01 | C32: Ingeniería | D32: Ampliar la batería de prueba a 50 preguntas con Mercadeo | E32: Salir a datos reales con más cobertura | F32: 50 preguntas con respuesta correcta calculada a mano | G32: 2 | H32: 0 | I32: 0 | J32: 0 | K32: 0 | L32: 0 | M32: 0 | N32: 0 | O32: 0 | P32: 0 | Q32: 2 | R32: 4 | S32: 6 | T32: 1 | U32: Expertos de Mercadeo

Sheet Priorizacion
A1: Priorización de candidatas
A2: Puntajes 1-5 en azul (criterio propio). El puntaje apoya la decisión, no la reemplaza.
A4: Criterio | B4: Peso | C4: IA-01 Copiloto | D4: IA-02 Promociones | E4: IA-05 Decisiones | F4: IA-04 Creativo | G4: Qué mide
A5: Valor (con evidencia) | B5: 1 | C5: 4 | D5: 3 | E5: 3 | F5: 2 | G5: Horas, dinero o riesgo con dato que lo respalde
A6: Urgencia | B6: 1 | C6: 4 | D6: 5 | E6: 4 | F6: 4 | G6: Plazo declarado y presión de Dirección
A7: Patrocinio | B7: 1 | C7: 4 | D7: 5 | E7: 5 | F7: 4 | G7: Peso y compromiso del patrocinador
A8: Facilidad (datos y riesgo) | B8: 1 | C8: 3 | D8: 2 | E8: 3 | F8: 3 | G8: Datos disponibles, sin bloqueos legales
A9: Reutilización | B9: 1 | C9: 5 | D9: 3 | E9: 3 | F9: 2 | G9: Sirve de base a otras iniciativas
A10: Total ponderado | C10: =SUMPRODUCT($B$5:$B$9,C5:C9) -> 20 | D10: =SUMPRODUCT($B$5:$B$9,D5:D9) -> 18 | E10: =SUMPRODUCT($B$5:$B$9,E5:E9) -> 18 | F10: =SUMPRODUCT($B$5:$B$9,F5:F9) -> 15
A11: Horas ingeniería (plan) | C11: =INDEX(Capacidad!$C$20:$C$23,MATCH("IA-01",Capacidad!$A$20:$A$23,0)) -> 142 | D11: =INDEX(Capacidad!$C$20:$C$23,MATCH("IA-02",Capacidad!$A$20:$A$23,0)) -> 12 | E11: =INDEX(Capacidad!$C$20:$C$23,MATCH("IA-05",Capacidad!$A$20:$A$23,0)) -> 12 | F11: =INDEX(Capacidad!$C$20:$C$23,MATCH("IA-04",Capacidad!$A$20:$A$23,0)) -> 0
A12: Resultado | C12: Seleccionada (D-11) | D12: Finalista: experimento | E12: Finalista: validación | F12: Prueba condicionada
A14: Pesos en 1 = todos los criterios valen igual. Cambie un peso para probar la sensibilidad del ranking.

Sheet Rutas
A1: Rutas de implementación de IA-01
A2: Pesos en amarillo y puntajes 1-5 en azul (criterio propio). El total es SUMPRODUCT.
A4: Criterio | B4: Peso | C4: A. Construir | D4: B. Comprar | E4: C. Componer | F4: D. Sin IA | G4: Por qué
A5: Valor | B5: 0.3 | C5: 4 | D5: 3 | E5: 4 | F5: 2 | G5: D no ataca el tiempo de análisis
A6: Velocidad | B6: 0.15 | C6: 4 | D6: 1 | E6: 3 | F6: 4 | G6: B: 0 contratos aprobados, ciclo de compra
A7: Esfuerzo | B7: 0.15 | C7: 3 | D7: 4 | E7: 4 | F7: 5 | G7: C reutiliza canal, modelo y datos
A8: Datos | B8: 0.15 | C8: 4 | D8: 3 | E8: 4 | F8: 4 | G8: Todas dependen de la tabla validada
A9: Riesgo | B9: 0.15 | C9: 3 | D9: 3 | E9: 4 | F9: 5 | G9: A: modelo sin contrato; B: dependencia de licencias
A10: Sostenibilidad | B10: 0.1 | C10: 3 | D10: 4 | E10: 4 | F10: 4 | G10: A: todo propio que mantener
A11: Total ponderado | B11: =SUM(B5:B10) -> 1 | C11: =SUMPRODUCT($B$5:$B$10,C5:C10) -> 3.6 | D11: =SUMPRODUCT($B$5:$B$10,D5:D10) -> 2.95 | E11: =SUMPRODUCT($B$5:$B$10,E5:E10) -> 3.85 | F11: =SUMPRODUCT($B$5:$B$10,F5:F10) -> 3.7
A12: Elegida | C12: =INDEX($C$4:$F$4,MATCH(MAX($C$11:$F$11),$C$11:$F$11,0)) -> C. Componer
A14: Lectura: C supera a D por poco porque D está contenida en C (la tabla validada es la base de ambas). Si en el piloto el grupo control mejora igual, se cae a D.

Sheet Capacidad
A1: Verificación de capacidad | 90 días
A2: Suma de la hoja PBIs (solo incluidos) en tres escenarios, contra lo disponible.
A4: Concepto | B4: Escenario | C4: Ingeniería (h) | D4: Datos (h) | E4: Seguridad (h) | F4: Expertos Mercadeo (h)
A5: Total planeado | B5: Mínimo | C5: =SUMPRODUCT(PBIs!$H$5:$H$32,PBIs!$T$5:$T$32) -> 126 | D5: =SUMPRODUCT(PBIs!$K$5:$K$32,PBIs!$T$5:$T$32) -> 23 | E5: =SUMPRODUCT(PBIs!$N$5:$N$32,PBIs!$T$5:$T$32) -> 7 | F5: =SUMPRODUCT(PBIs!$Q$5:$Q$32,PBIs!$T$5:$T$32) -> 12
A6: Total planeado | B6: Probable | C6: =SUMPRODUCT(PBIs!$I$5:$I$32,PBIs!$T$5:$T$32) -> 182 | D6: =SUMPRODUCT(PBIs!$L$5:$L$32,PBIs!$T$5:$T$32) -> 35 | E6: =SUMPRODUCT(PBIs!$O$5:$O$32,PBIs!$T$5:$T$32) -> 12 | F6: =SUMPRODUCT(PBIs!$R$5:$R$32,PBIs!$T$5:$T$32) -> 20
A7: Total planeado | B7: Máximo | C7: =SUMPRODUCT(PBIs!$J$5:$J$32,PBIs!$T$5:$T$32) -> 257 | D7: =SUMPRODUCT(PBIs!$M$5:$M$32,PBIs!$T$5:$T$32) -> 51 | E7: =SUMPRODUCT(PBIs!$P$5:$P$32,PBIs!$T$5:$T$32) -> 18 | F7: =SUMPRODUCT(PBIs!$S$5:$S$32,PBIs!$T$5:$T$32) -> 28
A8: Disponible | C8: =Datos!$C$27 -> 240 | D8: =Datos!$C$28 -> 35 | E8: =Datos!$C$29 -> 12 | F8: =Datos!$C$30 -> 20
A9: Holgura | B9: Mínimo | C9: =C$8-C5 -> 114 | D9: =D$8-D5 -> 12 | E9: =E$8-E5 -> 5 | F9: =F$8-F5 -> 8
A10: Holgura | B10: Probable | C10: =C$8-C6 -> 58 | D10: =D$8-D6 -> 0 | E10: =E$8-E6 -> 0 | F10: =F$8-F6 -> 0
A11: Holgura | B11: Máximo | C11: =C$8-C7 -> -17 | D11: =D$8-D7 -> -16 | E11: =E$8-E7 -> -6 | F11: =F$8-F7 -> -8
A12: Estado | B12: Mínimo | C12: =IF(C5<=C$8,"Cabe","EXCEDE") -> Cabe | D12: =IF(D5<=D$8,"Cabe","EXCEDE") -> Cabe | E12: =IF(E5<=E$8,"Cabe","EXCEDE") -> Cabe | F12: =IF(F5<=F$8,"Cabe","EXCEDE") -> Cabe
A13: Estado | B13: Probable | C13: =IF(C6<=C$8,"Cabe","EXCEDE") -> Cabe | D13: =IF(D6<=D$8,"Cabe","EXCEDE") -> Cabe | E13: =IF(E6<=E$8,"Cabe","EXCEDE") -> Cabe | F13: =IF(F6<=F$8,"Cabe","EXCEDE") -> Cabe
A14: Estado | B14: Máximo | C14: =IF(C7<=C$8,"Cabe","EXCEDE") -> EXCEDE | D14: =IF(D7<=D$8,"Cabe","EXCEDE") -> EXCEDE | E14: =IF(E7<=E$8,"Cabe","EXCEDE") -> EXCEDE | F14: =IF(F7<=F$8,"Cabe","EXCEDE") -> EXCEDE
A16: Reserva de ingeniería (escenario probable) | C16: =IF(C10>=Supuestos!$C$18,"Reserva OK","Sin reserva suficiente") -> Reserva OK
A18: Horas por frente (escenario probable)
A19: Frente | C19: Ingeniería (h) | D19: Datos (h) | E19: Seguridad (h) | F19: Expertos Mercadeo (h) | G19: Costo imputado interno (COP) | H19: Ingeniería máx (h)
A20: IA-01 | C20: =SUMPRODUCT((PBIs!$B$5:$B$32="IA-01")*PBIs!$I$5:$I$32*PBIs!$T$5:$T$32) -> 142 | D20: =SUMPRODUCT((PBIs!$B$5:$B$32="IA-01")*PBIs!$L$5:$L$32*PBIs!$T$5:$T$32) -> 27 | E20: =SUMPRODUCT((PBIs!$B$5:$B$32="IA-01")*PBIs!$O$5:$O$32*PBIs!$T$5:$T$32) -> 6 | F20: =SUMPRODUCT((PBIs!$B$5:$B$32="IA-01")*PBIs!$R$5:$R$32*PBIs!$T$5:$T$32) -> 18 | G20: =C20*Datos!$C$31+D20*Datos!$C$32+E20*Datos!$C$33 -> 17925000 | H20: =SUMPRODUCT((PBIs!$B$5:$B$32="IA-01")*PBIs!$J$5:$J$32*PBIs!$T$5:$T$32) -> 199
A21: IA-02 | C21: =SUMPRODUCT((PBIs!$B$5:$B$32="IA-02")*PBIs!$I$5:$I$32*PBIs!$T$5:$T$32) -> 12 | D21: =SUMPRODUCT((PBIs!$B$5:$B$32="IA-02")*PBIs!$L$5:$L$32*PBIs!$T$5:$T$32) -> 6 | E21: =SUMPRODUCT((PBIs!$B$5:$B$32="IA-02")*PBIs!$O$5:$O$32*PBIs!$T$5:$T$32) -> 0 | F21: =SUMPRODUCT((PBIs!$B$5:$B$32="IA-02")*PBIs!$R$5:$R$32*PBIs!$T$5:$T$32) -> 2 | G21: =C21*Datos!$C$31+D21*Datos!$C$32+E21*Datos!$C$33 -> 1770000 | H21: =SUMPRODUCT((PBIs!$B$5:$B$32="IA-02")*PBIs!$J$5:$J$32*PBIs!$T$5:$T$32) -> 18
A22: IA-04 | C22: =SUMPRODUCT((PBIs!$B$5:$B$32="IA-04")*PBIs!$I$5:$I$32*PBIs!$T$5:$T$32) -> 0 | D22: =SUMPRODUCT((PBIs!$B$5:$B$32="IA-04")*PBIs!$L$5:$L$32*PBIs!$T$5:$T$32) -> 0 | E22: =SUMPRODUCT((PBIs!$B$5:$B$32="IA-04")*PBIs!$O$5:$O$32*PBIs!$T$5:$T$32) -> 0 | F22: =SUMPRODUCT((PBIs!$B$5:$B$32="IA-04")*PBIs!$R$5:$R$32*PBIs!$T$5:$T$32) -> 0 | G22: =C22*Datos!$C$31+D22*Datos!$C$32+E22*Datos!$C$33 -> 0 | H22: =SUMPRODUCT((PBIs!$B$5:$B$32="IA-04")*PBIs!$J$5:$J$32*PBIs!$T$5:$T$32) -> 0
A23: IA-05 | C23: =SUMPRODUCT((PBIs!$B$5:$B$32="IA-05")*PBIs!$I$5:$I$32*PBIs!$T$5:$T$32) -> 12 | D23: =SUMPRODUCT((PBIs!$B$5:$B$32="IA-05")*PBIs!$L$5:$L$32*PBIs!$T$5:$T$32) -> 0 | E23: =SUMPRODUCT((PBIs!$B$5:$B$32="IA-05")*PBIs!$O$5:$O$32*PBIs!$T$5:$T$32) -> 2 | F23: =SUMPRODUCT((PBIs!$B$5:$B$32="IA-05")*PBIs!$R$5:$R$32*PBIs!$T$5:$T$32) -> 0 | G23: =C23*Datos!$C$31+D23*Datos!$C$32+E23*Datos!$C$33 -> 1500000 | H23: =SUMPRODUCT((PBIs!$B$5:$B$32="IA-05")*PBIs!$J$5:$J$32*PBIs!$T$5:$T$32) -> 18
A24: EXT | C24: =SUMPRODUCT((PBIs!$B$5:$B$32="EXT")*PBIs!$I$5:$I$32*PBIs!$T$5:$T$32) -> 6 | D24: =SUMPRODUCT((PBIs!$B$5:$B$32="EXT")*PBIs!$L$5:$L$32*PBIs!$T$5:$T$32) -> 2 | E24: =SUMPRODUCT((PBIs!$B$5:$B$32="EXT")*PBIs!$O$5:$O$32*PBIs!$T$5:$T$32) -> 2 | F24: =SUMPRODUCT((PBIs!$B$5:$B$32="EXT")*PBIs!$R$5:$R$32*PBIs!$T$5:$T$32) -> 0 | G24: =C24*Datos!$C$31+D24*Datos!$C$32+E24*Datos!$C$33 -> 1040000 | H24: =SUMPRODUCT((PBIs!$B$5:$B$32="EXT")*PBIs!$J$5:$J$32*PBIs!$T$5:$T$32) -> 8
A25: IA-09/10 | C25: =SUMPRODUCT((PBIs!$B$5:$B$32="IA-09/10")*PBIs!$I$5:$I$32*PBIs!$T$5:$T$32) -> 10 | D25: =SUMPRODUCT((PBIs!$B$5:$B$32="IA-09/10")*PBIs!$L$5:$L$32*PBIs!$T$5:$T$32) -> 0 | E25: =SUMPRODUCT((PBIs!$B$5:$B$32="IA-09/10")*PBIs!$O$5:$O$32*PBIs!$T$5:$T$32) -> 2 | F25: =SUMPRODUCT((PBIs!$B$5:$B$32="IA-09/10")*PBIs!$R$5:$R$32*PBIs!$T$5:$T$32) -> 0 | G25: =C25*Datos!$C$31+D25*Datos!$C$32+E25*Datos!$C$33 -> 1290000 | H25: =SUMPRODUCT((PBIs!$B$5:$B$32="IA-09/10")*PBIs!$J$5:$J$32*PBIs!$T$5:$T$32) -> 14
A26: Total | C26: =SUM(C20:C25) -> 182 | D26: =SUM(D20:D25) -> 35 | E26: =SUM(E20:E25) -> 12 | F26: =SUM(F20:F25) -> 20 | G26: =SUM(G20:G25) -> 23525000 | H26: =SUM(H20:H25) -> 257
A28: Desembolso externo pedido (COP) | C28: =Fondo_Externo!$F$10 -> 18600000 | D28: =IF(C28<=Datos!$C$34,"Dentro del techo","EXCEDE techo") -> Dentro del techo | H28: Detalle en Fondo_Externo; requiere aprobación (DAT-30); 0 contratos de IA (DAT-31)
A30: EXT = trabajo con el equipo externo de datos (fondo). IA-09/10 = evaluación de compra sin desembolso. Expertos sin tarifa [Por confirmar]. Rangos por PBI: estimación propia (D-15).

Sheet Fondo_Externo
A1: Fondo externo: uso propuesto (opción C, D-23)
A2: Techo de hasta COP 30 M condicionado a aprobación. Se pide solo lo que se va a usar.
A4: Uso | B4: Horas | C4: Tarifa (COP/h) | D4: Costo (COP) | E4: Incluido (1/0) | F4: Pedido (COP) | G4: Por qué
A5: 1. Horas externas de datos para la base única | B5: =Supuestos!$C$40 -> 15 | C5: =Supuestos!$C$35 -> 120000 | D5: =B5*C5 -> 1800000 | E5: 1 | F5: =D5*E5 -> 1800000 | G5: Cubre la brecha de Datos del escenario máximo del copiloto
A6: 2. Informes automáticos sobre la base única (IA-06, sin IA) | B6: =Supuestos!$C$37 -> 75 | C6: =Supuestos!$C$35 -> 120000 | D6: =B6*C6 -> 9000000 | E6: 1 | F6: =D6*E6 -> 9000000 | G6: Destraba un pedido sin horas internas de Datos; comparte horas con el copiloto: no sumar beneficios
A7: 3. Auditar datos de quiebres y pronóstico (IA-08/14) | B7: =Supuestos!$C$38 -> 40 | C7: =Supuestos!$C$35 -> 120000 | D7: =B7*C7 -> 4800000 | E7: 1 | F7: =D7*E7 -> 4800000 | G7: Arrancan en el mes 4 con línea base real; requiere aprobación explícita de Finanzas (va más allá del piloto)
A8: 4. Respaldo del costo del modelo de IA | D8: =Supuestos!$C$39 -> 3000000 | E8: 1 | F8: =D8*E8 -> 3000000 | G8: Solo si el modelo no está en el acuerdo de nube (S-24)
A10: Total pedido | F10: =SUM(F5:F8) -> 18600000
A11: Techo disponible | F11: =Datos!$C$34 -> 30000000
A12: No se pide | F12: =F11-F10 -> 11400000
A13: Estado | F13: =IF(F10<=F11,"Dentro del techo","EXCEDE el techo") -> Dentro del techo
A15: Cambie Incluido a 0 para ver las opciones: A = solo usos 1 y 4; B = usos 1, 2 y 4; C = todos. Cambie la tarifa en Supuestos S-31.

Sheet Uso_Recursos
A1: Uso de cada recurso en 90 días (escenario probable)
A2: Cierre de lo que abrimos: cada hora disponible tiene destino. Suma de la hoja PBIs.
A4: Frente | B4: Descripción | C4: Ingeniería (h) | D4: Datos (h) | E4: Seguridad (h) | F4: Expertos (h)
A5: IA-01 | B5: Copiloto de análisis | C5: =SUMPRODUCT((PBIs!$B$5:$B$32="IA-01")*PBIs!$I$5:$I$32*PBIs!$T$5:$T$32) -> 142 | D5: =SUMPRODUCT((PBIs!$B$5:$B$32="IA-01")*PBIs!$L$5:$L$32*PBIs!$T$5:$T$32) -> 27 | E5: =SUMPRODUCT((PBIs!$B$5:$B$32="IA-01")*PBIs!$O$5:$O$32*PBIs!$T$5:$T$32) -> 6 | F5: =SUMPRODUCT((PBIs!$B$5:$B$32="IA-01")*PBIs!$R$5:$R$32*PBIs!$T$5:$T$32) -> 18
A6: IA-02 | B6: Experimento de promociones | C6: =SUMPRODUCT((PBIs!$B$5:$B$32="IA-02")*PBIs!$I$5:$I$32*PBIs!$T$5:$T$32) -> 12 | D6: =SUMPRODUCT((PBIs!$B$5:$B$32="IA-02")*PBIs!$L$5:$L$32*PBIs!$T$5:$T$32) -> 6 | E6: =SUMPRODUCT((PBIs!$B$5:$B$32="IA-02")*PBIs!$O$5:$O$32*PBIs!$T$5:$T$32) -> 0 | F6: =SUMPRODUCT((PBIs!$B$5:$B$32="IA-02")*PBIs!$R$5:$R$32*PBIs!$T$5:$T$32) -> 2
A7: IA-05 | B7: Validación de decisiones | C7: =SUMPRODUCT((PBIs!$B$5:$B$32="IA-05")*PBIs!$I$5:$I$32*PBIs!$T$5:$T$32) -> 12 | D7: =SUMPRODUCT((PBIs!$B$5:$B$32="IA-05")*PBIs!$L$5:$L$32*PBIs!$T$5:$T$32) -> 0 | E7: =SUMPRODUCT((PBIs!$B$5:$B$32="IA-05")*PBIs!$O$5:$O$32*PBIs!$T$5:$T$32) -> 2 | F7: =SUMPRODUCT((PBIs!$B$5:$B$32="IA-05")*PBIs!$R$5:$R$32*PBIs!$T$5:$T$32) -> 0
A8: IA-09/10 | B8: Evaluación de compra: soporte y contratos | C8: =SUMPRODUCT((PBIs!$B$5:$B$32="IA-09/10")*PBIs!$I$5:$I$32*PBIs!$T$5:$T$32) -> 10 | D8: =SUMPRODUCT((PBIs!$B$5:$B$32="IA-09/10")*PBIs!$L$5:$L$32*PBIs!$T$5:$T$32) -> 0 | E8: =SUMPRODUCT((PBIs!$B$5:$B$32="IA-09/10")*PBIs!$O$5:$O$32*PBIs!$T$5:$T$32) -> 2 | F8: =SUMPRODUCT((PBIs!$B$5:$B$32="IA-09/10")*PBIs!$R$5:$R$32*PBIs!$T$5:$T$32) -> 0
A9: EXT | B9: Trabajo con el equipo externo de datos | C9: =SUMPRODUCT((PBIs!$B$5:$B$32="EXT")*PBIs!$I$5:$I$32*PBIs!$T$5:$T$32) -> 6 | D9: =SUMPRODUCT((PBIs!$B$5:$B$32="EXT")*PBIs!$L$5:$L$32*PBIs!$T$5:$T$32) -> 2 | E9: =SUMPRODUCT((PBIs!$B$5:$B$32="EXT")*PBIs!$O$5:$O$32*PBIs!$T$5:$T$32) -> 2 | F9: =SUMPRODUCT((PBIs!$B$5:$B$32="EXT")*PBIs!$R$5:$R$32*PBIs!$T$5:$T$32) -> 0
A10: IA-04 | B10: Prueba creativa (si se activa, S-13) | C10: =SUMPRODUCT((PBIs!$B$5:$B$32="IA-04")*PBIs!$I$5:$I$32*PBIs!$T$5:$T$32) -> 0 | D10: =SUMPRODUCT((PBIs!$B$5:$B$32="IA-04")*PBIs!$L$5:$L$32*PBIs!$T$5:$T$32) -> 0 | E10: =SUMPRODUCT((PBIs!$B$5:$B$32="IA-04")*PBIs!$O$5:$O$32*PBIs!$T$5:$T$32) -> 0 | F10: =SUMPRODUCT((PBIs!$B$5:$B$32="IA-04")*PBIs!$R$5:$R$32*PBIs!$T$5:$T$32) -> 0
A11: Asignado | C11: =SUM(C5:C10) -> 182 | D11: =SUM(D5:D10) -> 35 | E11: =SUM(E5:E10) -> 12 | F11: =SUM(F5:F10) -> 20
A12: Disponible | C12: =Datos!$C$27 -> 240 | D12: =Datos!$C$28 -> 35 | E12: =Datos!$C$29 -> 12 | F12: =Datos!$C$30 -> 20
A13: Reserva sin asignar | B13: Ingeniería: margen para pedidos nuevos de Dirección (S-14) | C13: =C12-C11 -> 58 | D13: =D12-D11 -> 0 | E13: =E12-E11 -> 0 | F13: =F12-F11 -> 0
A14: Uso | C14: =C11/C12 -> 0.75833333 | D14: =D11/D12 -> 1 | E14: =E11/E12 -> 1 | F14: =F11/F12 -> 1
A15: Estado | C15: =IF(C11<=C12,"Cabe","EXCEDE") -> Cabe | D15: =IF(D11<=D12,"Cabe","EXCEDE") -> Cabe | E15: =IF(E11<=E12,"Cabe","EXCEDE") -> Cabe | F15: =IF(F11<=F12,"Cabe","EXCEDE") -> Cabe
A16: Reserva de ingeniería ≥ S-14 | C16: =IF(C13>=Supuestos!$C$18,"Reserva OK","Reserva insuficiente") -> Reserva OK
A18: Dinero externo pedido (COP) | C18: =Fondo_Externo!F10 -> 18600000
A19: Dinero externo no pedido (COP) | C19: =Fondo_Externo!F12 -> 11400000

Sheet Portafolio
A1: Portafolio de 15 solicitudes
A2: Esfuerzo = rango del solicitante (no validado). Decisión preliminar del diagnóstico.
A4: ID | B4: Iniciativa | C4: Familia | D4: Patrocinador | E4: Esfuerzo bajo (h) | F4: Esfuerzo alto (h) | G4: Urgencia declarada | H4: Decisión preliminar | I4: Ruta
A5: IA-01 | B5: Copiloto de análisis comercial Brío | C5: 1. Análisis comercial | D5: Mercadeo | E5: 60 | F5: 110 | G5: Próximas 8 semanas | H5: Iniciar (cifras confiables) | I5: IA + datos
A6: IA-02 | B6: Recomendador de promociones | C6: 2. Ventas y promociones | D6: CEO / Comercial | E6: 140 | F6: 240 | G6: Demostración en 30 días | H6: Investigar / experimentar | I6: Diseño de experimento
A7: IA-03 | B7: Alertas de anomalías comerciales | C7: 6. Control y anomalías | D7: Datos / Contraloría | E7: 35 | F7: 65 | G7: Próximas 6 semanas | H7: Iniciar dentro de IA-01 | I7: Reglas, sin IA
A8: IA-04 | B8: Generador de variantes creativas | C8: 3. Creatividad | D8: CEO / Mercadeo | E8: 45 | F8: 95 | G8: Demo para comité en 30 días | H8: Experimentar (condicionado) | I8: Herramienta existente
A9: IA-05 | B9: Asistente para Análisis de Decisión | C9: 4. Decisiones | D9: CEO / Planeación | E9: 70 | F9: 120 | G9: Primer piloto en 45 días | H9: Investigar / experimentar | I9: Validación con rúbrica
A10: IA-06 | B10: Automatizar informes comerciales | C10: 1. Análisis comercial | D10: Comercial | E10: 40 | F10: 75 | G10: Este trimestre | H10: Posponer (sin horas de Datos) | I10: Automatización, sin IA
A11: IA-07 | B11: Síntesis de investigaciones de consumidor | C11: 1. Análisis comercial | D11: CEO / Investigación | E11: 45 | F11: 85 | G11: En 60 días | H11: Posponer | I11: —
A12: IA-08 | B12: Prevención de quiebres de inventario | C12: 5. Predicción clásica | D12: Operaciones | E12: 130 | F12: 230 | G12: Próximo trimestre | H12: Posponer; medir bien | I12: Analítica predictiva
A13: IA-09 | B13: Asistente de soporte interno | C13: 7. Asistentes internos | D13: Servicios internos | E13: 60 | F13: 110 | G13: Sin fecha | H13: Posponer; preparar compra | I13: Comprar
A14: IA-10 | B14: Revisión inicial de contratos | C14: 7. Asistentes internos | D14: Jurídica | E14: 95 | F14: 170 | G14: Piloto en 60 días | H14: Posponer; clasificar y medir | I14: Comprar / evaluar
A15: IA-11 | B15: Predicción de riesgo de recaudo | C15: 5. Predicción clásica | D15: Finanzas | E15: 110 | F15: 190 | G15: Sin fecha | H15: No abordar ahora | I15: —
A16: IA-12 | B16: Adaptación creativa a filiales | C16: 3. Creatividad | D16: Mercadeo regional | E16: 65 | F16: 125 | G16: Segundo semestre | H16: Posponer | I16: —
... A19: IA-15 | B19: Control de reembolsos comerciales | C19: 6. Control y anomalías | D19: Finanzas / Auditoría | E19: 90 | F19: 160 | G19: Urgente (Auditoría) | H19: Resolver sin IA | I19: Reglas + muestreo
D21: Total solicitado | E21: =SUM(E5:E19) -> 1215 | F21: =SUM(F5:F19) -> 2185
D22: Veces la capacidad de ingeniería | E22: =E21/Datos!$C$27 -> 5.0625 | F22: =F21/Datos!$C$27 -> 9.1041667
D23: Pedidos del CEO (IA-02+IA-04+IA-05) | E23: =E6+E8+E9 -> 255 | F23: =F6+F8+F9 -> 455
A25: Fuente: 02_Portafolio_IA.xlsx, hoja Solicitudes. Decisiones: hoja Decisiones.

Sheet Decisiones
A1: Registro de decisiones
A2: Decide: Sergio (Ingeniero de Producto IA). Fecha de registro.
A4: ID | B4: Fecha | C4: Decisión | D4: Alternativas descartadas | E4: Quién
A5: D-01 | B5: 2026-10-21 | C5: Agrupar las 15 solicitudes en 7 familias por personas, tipo de solución o valor prometido | D5: — | E5: Sergio
A6: D-02 | B6: 2026-10-21 | C6: Familia 1: copiloto con cifras confiables (definición única de ventas netas + asistente que consulta, no calcula) | D6: A: copiloto sobre datos actuales; C: solo BI sin IA | E6: Sergio
A7: D-03 | B7: 2026-10-21 | C7: Familia 2: IA-02 se valida con experimento en regiones comparables; IA-13 se pospone | D7: A: construir recomendador; C: no abordar | E7: Sergio
A8: D-04 | B8: 2026-10-21 | C8: Familia 3: IA-04 prueba corta con herramienta existente; IA-12 se pospone | D8: A: construir generador; C: posponer | E8: Sergio
A9: D-05 | B9: 2026-10-21 | C9: Familia 4: IA-05 se valida con rúbrica de calidad del documento de decisión en 45 días | D9: A: construir asistente; C: posponer | E9: Sergio
A10: D-06 | B10: 2026-10-21 | C10: Familia 5: IA-08 e IA-14 se posponen y se unen; Planeación mide bien primero. IA-11 no se aborda | D10: A: iniciar IA-14; C: no abordar | E10: Sergio
A11: D-07 | B11: 2026-10-21 | C11: Familia 6: reglas sin IA. IA-03 dentro de IA-01; IA-15 reglas + muestreo de Auditoría | D11: A: detector con IA; C: posponer | E11: Sergio
A12: D-08 | B12: 2026-10-21 | C12: Familia 7: preparar y evaluar compra; IA-09 actualizar base de conocimiento, IA-10 clasificar y medir | D12: A: construir ambos; C: no abordar | E12: Sergio
A13: D-09 | B13: 2026-10-21 | C13: Capacidad: IA-04 condicionada (herramienta ya licenciada y expertos libres); IA-06 fuera del trimestre; 40 h de ingeniería como reserva | D13: A: mantener los 5 frentes sin condición; C: quitar IA-02 | E13: Sergio
A14: D-10 | B14: 2026-10-21 | C14: Finalistas: IA-01, IA-02, IA-05. IA-04 sigue como prueba condicionada fuera de la comparación | D14: B: IA-01, IA-02, IA-04; C: IA-01, IA-05, IA-04 | E14: Sergio
A15: D-11 | B15: 2026-10-21 | C15: Iniciativa seleccionada: IA-01. IA-02 e IA-05 avanzan en paralelo como experimentos | D15: IA-02 o IA-05 como seleccionada | E15: Sergio
... A30: D-12 | B30: 2026-10-21 | C30: Gobierno de cambios: entra algo, sale algo; reserva de 40 h; sin ficha no entra; revisión quincenal con el CEO; máximo 1 construcción y 2 validaciones a la vez | D30: — | E30: Sergio
